<?xml version="1.0" encoding="utf-8"?>
<!-- This URDF was automatically created by SolidWorks to URDF Exporter! Originally created by Stephen Brawner (brawner@gmail.com) 
     Commit Version: 1.6.0-4-g7f85cfe  Build Version: 1.6.7995.38578
     For more information, please see http://wiki.ros.org/sw_urdf_exporter -->
<robot
  name="arm">
  <link
    name="base_link">
    <visual>
      <origin
        xyz="0 0 0"
        rpy="0 0 0" />
      <geometry>
        <box size="2 2 2" />
      </geometry>
      <material
        name="">
        <color
          rgba="0.898039215686275 0.917647058823529 0.929411764705882 1" />
      </material>
    </visual>
  </link>
  <link
    name="link1">
    <visual>
      <origin
        xyz="0 0 0"
        rpy="0 0 0" />
      <geometry>
        <cylinder radius="1" length="0.5"/>
      </geometry>
      <material
        name="">
        <color
          rgba="0.298039215686275 0.298039215686275 0.298039215686275 1" />
      </material>
    </visual>
  </link>
  <joint
    name="joint1"
    type="continuous">
    <origin
      xyz="0 0 1"
      rpy="0 0 0" />
    <parent
      link="base_link" />
    <child
      link="link1" />
    <axis
      xyz="0 0 1" />
  </joint>
  <!-- <link
    name="link2">
    <inertial>
      <origin
        xyz="-0.0673676204144748 -0.0227999999999996 1.52655665885959E-16"
        rpy="0 0 0" />
      <mass
        value="0.0538438117267846" />
      <inertia
        ixx="3.91939181590137E-06"
        ixy="2.05040921688493E-21"
        ixz="5.15783507873765E-19"
        iyy="0.00012782014857789"
        iyz="5.13327241807089E-21"
        izz="0.000123981522479579" />
    </inertial>
    <visual>
      <origin
        xyz="0 0 0"
        rpy="0 0 0" />
      <geometry>
        <mesh
          filename="package://urdf_control_arm/meshes/link2.STL" />
      </geometry>
      <material
        name="">
        <color
          rgba="0.298039215686275 0.298039215686275 0.298039215686275 1" />
      </material>
    </visual>
    <collision>
      <origin
        xyz="0 0 0"
        rpy="0 0 0" />
      <geometry>
        <mesh
          filename="package://urdf_control_arm/meshes/link2.STL" />
      </geometry>
    </collision>
  </link>
  <joint
    name="joint2"
    type="fixed">
    <origin
      xyz="-0.192016669750803 0 -0.0358327204326333"
      rpy="3.14159265358979 0.0123247882232276 3.14159265358979" />
    <parent
      link="link1" />
    <child
      link="link2" />
    <axis
      xyz="0 0 0" />
  </joint>
  <link
    name="link3">
    <inertial>
      <origin
        xyz="-0.0155968087940944 -0.0227700212036444 -0.010434686550014"
        rpy="0 0 0" />
      <mass
        value="0.0692620585470794" />
      <inertia
        ixx="1.17064344223662E-05"
        ixy="3.92390234029933E-08"
        ixz="-1.75533296343905E-07"
        iyy="1.14358954522364E-05"
        iyz="1.01793251778908E-09"
        izz="1.84682970090164E-05" />
    </inertial>
    <visual>
      <origin
        xyz="0 0 0"
        rpy="0 0 0" />
      <geometry>
        <mesh
          filename="package://urdf_control_arm/meshes/link3.STL" />
      </geometry>
      <material
        name="">
        <color
          rgba="0.298039215686275 0.298039215686275 0.298039215686275 1" />
      </material>
    </visual>
    <collision>
      <origin
        xyz="0 0 0"
        rpy="0 0 0" />
      <geometry>
        <mesh
          filename="package://urdf_control_arm/meshes/link3.STL" />
      </geometry>
    </collision>
  </link>
  <joint
    name="joint3"
    type="fixed">
    <origin
      xyz="-0.14 -0.0455999999999996 0"
      rpy="-3.14159265358979 0 0" />
    <parent
      link="link2" />
    <child
      link="link3" />
    <axis
      xyz="0 0 0" />
  </joint>
  <link
    name="link4">
    <inertial>
      <origin
        xyz="-2.32710015607741E-05 0.0119209248746 -0.00769983529452291"
        rpy="0 0 0" />
      <mass
        value="0.0409780706300096" />
      <inertia
        ixx="7.17693454798754E-06"
        ixy="5.22236315072449E-09"
        ixz="-3.53466756714768E-08"
        iyy="1.20222456499346E-05"
        iyz="-1.61296230963784E-07"
        izz="7.90882118956884E-06" />
    </inertial>
    <visual>
      <origin
        xyz="0 0 0"
        rpy="0 0 0" />
      <geometry>
        <mesh
          filename="package://urdf_control_arm/meshes/link4.STL" />
      </geometry>
      <material
        name="">
        <color
          rgba="1 1 1 1" />
      </material>
    </visual>
    <collision>
      <origin
        xyz="0 0 0"
        rpy="0 0 0" />
      <geometry>
        <mesh
          filename="package://urdf_control_arm/meshes/link4.STL" />
      </geometry>
    </collision>
  </link>
  <joint
    name="joint4"
    type="fixed">
    <origin
      xyz="-0.0477932279381449 -0.0128064310648106 -0.0240173937742402"
      rpy="-0.0259371763528233 -0.00942454291293869 1.57104082403284" />
    <parent
      link="link3" />
    <child
      link="link4" />
    <axis
      xyz="0 0 0" />
  </joint>
  <link
    name="link5">
    <inertial>
      <origin
        xyz="-6.90315758842283E-05 0.0185135103478107 -6.67224774364428E-05"
        rpy="0 0 0" />
      <mass
        value="0.0366230967693051" />
      <inertia
        ixx="5.97642065709567E-06"
        ixy="-2.76956956367271E-10"
        ixz="1.79216409585139E-09"
        iyy="1.00617294439248E-05"
        iyz="-6.83713991812404E-09"
        izz="6.33309751282362E-06" />
    </inertial>
    <visual>
      <origin
        xyz="0 0 0"
        rpy="0 0 0" />
      <geometry>
        <mesh
          filename="package://urdf_control_arm/meshes/link5.STL" />
      </geometry>
      <material
        name="">
        <color
          rgba="0.298039215686275 0.298039215686275 0.298039215686275 1" />
      </material>
    </visual>
    <collision>
      <origin
        xyz="0 0 0"
        rpy="0 0 0" />
      <geometry>
        <mesh
          filename="package://urdf_control_arm/meshes/link5.STL" />
      </geometry>
    </collision>
  </link>
  <joint
    name="joint5"
    type="fixed">
    <origin
      xyz="-0.00997 0.013199999999998 -0.0324000000000008"
      rpy="-1.57079632679483 0 -3.04133909398124" />
    <parent
      link="link4" />
    <child
      link="link5" />
    <axis
      xyz="0 0 0" />
  </joint>
  <link
    name="link6">
    <inertial>
      <origin
        xyz="0.00448513361665756 0.0176005994190371 0.00594759101106926"
        rpy="0 0 0" />
      <mass
        value="0.0106748612946697" />
      <inertia
        ixx="2.54888987230047E-06"
        ixy="9.28161169461107E-08"
        ixz="3.97296025187969E-14"
        iyy="2.44171514508945E-06"
        iyz="5.56039159469918E-15"
        izz="3.55862075124143E-07" />
    </inertial>
    <visual>
      <origin
        xyz="0 0 0"
        rpy="0 0 0" />
      <geometry>
        <mesh
          filename="package://urdf_control_arm/meshes/link6.STL" />
      </geometry>
      <material
        name="">
        <color
          rgba="1 1 1 1" />
      </material>
    </visual>
    <collision>
      <origin
        xyz="0 0 0"
        rpy="0 0 0" />
      <geometry>
        <mesh
          filename="package://urdf_control_arm/meshes/link6.STL" />
      </geometry>
    </collision>
  </link>
  <joint
    name="joint6"
    type="fixed">
    <origin
      xyz="0.0114632777855543 0.0400028441067219 -0.030405751032087"
      rpy="-0.247444244668487 -0.186768794681046 2.63503698813776" />
    <parent
      link="link5" />
    <child
      link="link6" />
    <axis
      xyz="0 0 0" />
  </joint> -->
</robot>