<?xml version="1.0" encoding="utf-8"?>
<!-- This URDF was automatically created by SolidWorks to URDF Exporter! Originally created by Stephen Brawner (brawner@gmail.com) 
     Commit Version: 1.6.0-4-g7f85cfe  Build Version: 1.6.7995.38578
     For more information, please see http://wiki.ros.org/sw_urdf_exporter -->
<robot
  name="robot2">
  <link
    name="base_link">
    <inertial>
      <origin
        xyz="-0.0701829147785119 0.0509547676769668 0.12781073514068"
        rpy="0 0 0" />
      <mass
        value="1.24817506212786" />
      <inertia
        ixx="0.00337795459495386"
        ixy="-7.63530306910811E-07"
        ixz="2.62159249188306E-06"
        iyy="0.00367217131754412"
        iyz="0.000119973959588174"
        izz="0.00510242704517102" />
    </inertial>
    <visual>
      <origin
        xyz="0 0 0"
        rpy="0 0 0" />
      <geometry>
        <mesh
          filename="package://example_urdf_description/urdf/base_link.STL" />
      </geometry>
      <material
        name="">
        <color
          rgba="1 1 1 1" />
      </material>
    </visual>
    <collision>
      <origin
        xyz="0 0 0"
        rpy="0 0 0" />
      <geometry>
        <mesh
          filename="package://example_urdf_description/urdf/base_link.STL" />
      </geometry>
    </collision>
  </link>
  <link
    name="link1">
    <inertial>
      <origin
        xyz="-5.91252113768537E-07 0.0822549076127321 0.0130939326706805"
        rpy="0 0 0" />
      <mass
        value="3.45633560104234" />
      <inertia
        ixx="0.0140386764717093"
        ixy="-3.70559606285327E-08"
        ixz="2.62624158988822E-07"
        iyy="0.0118933802335214"
        iyz="-0.000227442711188719"
        izz="0.0124437380528522" />
    </inertial>
    <visual>
      <origin
        xyz="0 0 0"
        rpy="0 0 0" />
      <geometry>
        <mesh
          filename="package://example_urdf_description/urdf/link1.STL" />
      </geometry>
      <material
        name="">
        <color
          rgba="1 1 1 1" />
      </material>
    </visual>
    <collision>
      <origin
        xyz="0 0 0"
        rpy="0 0 0" />
      <geometry>
        <mesh
          filename="package://example_urdf_description/urdf/link1.STL" />
      </geometry>
    </collision>
  </link>
  <joint
    name="joint1"
    type="continuous">
    <origin
      xyz="-0.0702629032816481 0.0488280110823862 0.168097564394159"
      rpy="1.5707963267949 0 -0.771225038056414" />
    <parent
      link="base_link" />
    <child
      link="link1" />
    <axis
      xyz="0 1 0" />
  </joint>
  <link
    name="link2">
    <inertial>
      <origin
        xyz="1.70229410101363E-06 0.18974678071681 -0.00353997730750166"
        rpy="0 0 0" />
      <mass
        value="8.08752965176624" />
      <inertia
        ixx="0.285723822163904"
        ixy="-2.05110800014771E-06"
        ixz="2.25782177967759E-07"
        iyy="0.0206370446473606"
        iyz="0.000578891768871088"
        izz="0.28305748909231" />
    </inertial>
    <visual>
      <origin
        xyz="0 0 0"
        rpy="0 0 0" />
      <geometry>
        <mesh
          filename="package://example_urdf_description/urdf/link2.STL" />
      </geometry>
      <material
        name="">
        <color
          rgba="1 1 1 1" />
      </material>
    </visual>
    <collision>
      <origin
        xyz="0 0 0"
        rpy="0 0 0" />
      <geometry>
        <mesh
          filename="package://example_urdf_description/urdf/link2.STL" />
      </geometry>
    </collision>
  </link>
  <joint
    name="joint2"
    type="continuous">
    <origin
      xyz="0 0.0814000000000002 0.179787490905011"
      rpy="0 0 -0.0211286164016568" />
    <parent
      link="link1" />
    <child
      link="link2" />
    <axis
      xyz="0 0 1" />
  </joint>
</robot>